    for pattern in self.url_patterns:
  File "C:\Users\Camila Riquelme\Documents\GitHub\pythontalentodigital2020\CODINGDOJO\django\djangoPy3Env\lib\site-packages\django\utils\functional.py", line 80, in __get__
    res = instance.__dict__[self.name] = self.func(instance)
  File "C:\Users\Camila Riquelme\Documents\GitHub\pythontalentodigital2020\CODINGDOJO\django\djangoPy3Env\lib\site-packages\django\urls\resolvers.py", line 579, in url_patterns
    patterns = getattr(self.urlconf_module, "urlpatterns", self.urlconf_module)
  File "C:\Users\Camila Riquelme\Documents\GitHub\pythontalentodigital2020\CODINGDOJO\django\djangoPy3Env\lib\site-packages\django\utils\functional.py", line 80, in __get__
    res = instance.__dict__[self.name] = self.func(instance)
  File "C:\Users\Camila Riquelme\Documents\GitHub\pythontalentodigital2020\CODINGDOJO\django\djangoPy3Env\lib\site-packages\django\urls\resolvers.py", line 572, in urlconf_module
    return import_module(self.urlconf_name)
  File "C:\Program Files\WindowsApps\PythonSoftwareFoundation.Python.3.9_3.9.496.0_x64__qbz5n2kfra8p0\lib\importlib\__init__.py", line 127, in import_module
    return _bootstrap._gcd_import(name[level:], package, level)
  File "<frozen importlib._bootstrap>", line 1030, in _gcd_import
  File "<frozen importlib._bootstrap>", line 1007, in _find_and_load
  File "<frozen importlib._bootstrap>", line 986, in _find_and_load_unlocked
  File "<frozen importlib._bootstrap>", line 680, in _load_unlocked
  File "<frozen importlib._bootstrap_external>", line 790, in exec_module
  File "<frozen importlib._bootstrap>", line 228, in _call_with_frames_removed
  File "C:\Users\Camila Riquelme\Desktop\pro1\pro1\urls.py", line 21, in <module>
    path('', include('app1.urls')),
  File "C:\Users\Camila Riquelme\Documents\GitHub\pythontalentodigital2020\CODINGDOJO\django\djangoPy3Env\lib\site-packages\django\urls\conf.py", line 34, 
in include
    urlconf_module = import_module(urlconf_module)
  File "C:\Program Files\WindowsApps\PythonSoftwareFoundation.Python.3.9_3.9.496.0_x64__qbz5n2kfra8p0\lib\importlib\__init__.py", line 127, in import_module
    return _bootstrap._gcd_import(name[level:], package, level)
  File "<frozen importlib._bootstrap>", line 1030, in _gcd_import
  File "<frozen importlib._bootstrap>", line 1007, in _find_and_load
  File "<frozen importlib._bootstrap>", line 986, in _find_and_load_unlocked
  File "<frozen importlib._bootstrap>", line 680, in _load_unlocked
  File "<frozen importlib._bootstrap_external>", line 790, in exec_module
  File "<frozen importlib._bootstrap>", line 228, in _call_with_frames_removed
  File "C:\Users\Camila Riquelme\Desktop\pro1\app1\urls.py", line 2, in <module>
    from . import views
  File "C:\Users\Camila Riquelme\Desktop\pro1\app1\views.py", line 9
    }
    ^
SyntaxError: invalid syntax
C:\Users\Camila Riquelme\Desktop\pro1\app1\views.py changed, reloading.
Watching for file changes with StatReloader
Performing system checks...

System check identified no issues (0 silenced).
February 23, 2021 - 20:07:11
Django version 2.2.4, using settings 'pro1.settings'
Starting development server at http://127.0.0.1:8000/
Quit the server with CTRL-BREAK.
C:\Users\Camila Riquelme\Desktop\pro1\app1\views.py changed, reloading.
Watching for file changes with StatReloader
Performing system checks...

System check identified no issues (0 silenced).
February 23, 2021 - 20:07:24
Django version 2.2.4, using settings 'pro1.settings'
Starting development server at http://127.0.0.1:8000/
Quit the server with CTRL-BREAK.
<QuerySet [<house: house object (1)>]>
[23/Feb/2021 20:07:27] "GET / HTTP/1.1" 200 0
<QuerySet [<house: house object (1)>]>
[23/Feb/2021 20:08:43] "GET / HTTP/1.1" 200 316
<QuerySet [<house: house object (1)>, <house: house object (2)>]>
[23/Feb/2021 20:11:11] "GET / HTTP/1.1" 200 349
<QuerySet [<house: house object (1)>, <house: house object (2)>]>
[23/Feb/2021 20:14:36] "GET / HTTP/1.1" 200 328
<QuerySet [<house: house object (1)>, <house: house object (2)>]>
[23/Feb/2021 20:15:08] "GET / HTTP/1.1" 200 315
C:\Users\Camila Riquelme\Desktop\pro1\app1\views.py changed, reloading.
Watching for file changes with StatReloader
Performing system checks...

System check identified no issues (0 silenced).
February 23, 2021 - 20:16:00
Django version 2.2.4, using settings 'pro1.settings'
Starting development server at http://127.0.0.1:8000/
Quit the server with CTRL-BREAK.
C:\Users\Camila Riquelme\Desktop\pro1\app1\views.py changed, reloading.
Watching for file changes with StatReloader
Performing system checks...

Exception in thread django-main-thread:
Traceback (most recent call last):
  File "C:\Program Files\WindowsApps\PythonSoftwareFoundation.Python.3.9_3.9.496.0_x64__qbz5n2kfra8p0\lib\threading.py", line 954, in _bootstrap_inner     
    self.run()
  File "C:\Program Files\WindowsApps\PythonSoftwareFoundation.Python.3.9_3.9.496.0_x64__qbz5n2kfra8p0\lib\threading.py", line 892, in run
    self._target(*self._args, **self._kwargs)
  File "C:\Users\Camila Riquelme\Documents\GitHub\pythontalentodigital2020\CODINGDOJO\django\djangoPy3Env\lib\site-packages\django\utils\autoreload.py", line 54, in wrapper
    fn(*args, **kwargs)
  File "C:\Users\Camila Riquelme\Documents\GitHub\pythontalentodigital2020\CODINGDOJO\django\djangoPy3Env\lib\site-packages\django\core\management\commands\runserver.py", line 117, in inner_run
    self.check(display_num_errors=True)
  File "C:\Users\Camila Riquelme\Documents\GitHub\pythontalentodigital2020\CODINGDOJO\django\djangoPy3Env\lib\site-packages\django\core\management\base.py", line 387, in check
    all_issues = self._run_checks(
  File "C:\Users\Camila Riquelme\Documents\GitHub\pythontalentodigital2020\CODINGDOJO\django\djangoPy3Env\lib\site-packages\django\core\management\base.py", line 377, in _run_checks
    return checks.run_checks(**kwargs)
  File "C:\Users\Camila Riquelme\Documents\GitHub\pythontalentodigital2020\CODINGDOJO\django\djangoPy3Env\lib\site-packages\django\core\checks\registry.py", line 72, in run_checks
    new_errors = check(app_configs=app_configs)
  File "C:\Users\Camila Riquelme\Documents\GitHub\pythontalentodigital2020\CODINGDOJO\django\djangoPy3Env\lib\site-packages\django\core\checks\urls.py", line 13, in check_url_config
    return check_resolver(resolver)
  File "C:\Users\Camila Riquelme\Documents\GitHub\pythontalentodigital2020\CODINGDOJO\django\djangoPy3Env\lib\site-packages\django\core\checks\urls.py", line 23, in check_resolver
    return check_method()
  File "C:\Users\Camila Riquelme\Documents\GitHub\pythontalentodigital2020\CODINGDOJO\django\djangoPy3Env\lib\site-packages\django\urls\resolvers.py", line 398, in check
    for pattern in self.url_patterns:
  File "C:\Users\Camila Riquelme\Documents\GitHub\pythontalentodigital2020\CODINGDOJO\django\djangoPy3Env\lib\site-packages\django\utils\functional.py", line 80, in __get__
    res = instance.__dict__[self.name] = self.func(instance)
  File "C:\Users\Camila Riquelme\Documents\GitHub\pythontalentodigital2020\CODINGDOJO\django\djangoPy3Env\lib\site-packages\django\urls\resolvers.py", line 579, in url_patterns
    patterns = getattr(self.urlconf_module, "urlpatterns", self.urlconf_module)
  File "C:\Users\Camila Riquelme\Documents\GitHub\pythontalentodigital2020\CODINGDOJO\django\djangoPy3Env\lib\site-packages\django\utils\functional.py", line 80, in __get__
    res = instance.__dict__[self.name] = self.func(instance)
  File "C:\Users\Camila Riquelme\Documents\GitHub\pythontalentodigital2020\CODINGDOJO\django\djangoPy3Env\lib\site-packages\django\urls\resolvers.py", line 572, in urlconf_module
    return import_module(self.urlconf_name)
  File "C:\Program Files\WindowsApps\PythonSoftwareFoundation.Python.3.9_3.9.496.0_x64__qbz5n2kfra8p0\lib\importlib\__init__.py", line 127, in import_module
    return _bootstrap._gcd_import(name[level:], package, level)
  File "<frozen importlib._bootstrap>", line 1030, in _gcd_import
  File "<frozen importlib._bootstrap>", line 1007, in _find_and_load
  File "<frozen importlib._bootstrap>", line 986, in _find_and_load_unlocked
  File "<frozen importlib._bootstrap>", line 680, in _load_unlocked
  File "<frozen importlib._bootstrap_external>", line 790, in exec_module
  File "<frozen importlib._bootstrap>", line 228, in _call_with_frames_removed
  File "C:\Users\Camila Riquelme\Desktop\pro1\pro1\urls.py", line 21, in <module>
    path('', include('app1.urls')),
  File "C:\Users\Camila Riquelme\Documents\GitHub\pythontalentodigital2020\CODINGDOJO\django\djangoPy3Env\lib\site-packages\django\urls\conf.py", line 34, 
in include
    urlconf_module = import_module(urlconf_module)
  File "C:\Program Files\WindowsApps\PythonSoftwareFoundation.Python.3.9_3.9.496.0_x64__qbz5n2kfra8p0\lib\importlib\__init__.py", line 127, in import_module
    return _bootstrap._gcd_import(name[level:], package, level)
  File "<frozen importlib._bootstrap>", line 1030, in _gcd_import
  File "<frozen importlib._bootstrap>", line 1007, in _find_and_load
  File "<frozen importlib._bootstrap>", line 986, in _find_and_load_unlocked
  File "<frozen importlib._bootstrap>", line 680, in _load_unlocked
  File "<frozen importlib._bootstrap_external>", line 790, in exec_module
  File "<frozen importlib._bootstrap>", line 228, in _call_with_frames_removed
  File "C:\Users\Camila Riquelme\Desktop\pro1\app1\urls.py", line 2, in <module>
    from . import views
  File "C:\Users\Camila Riquelme\Desktop\pro1\app1\views.py", line 13
    def wizard
              ^
SyntaxError: invalid syntax
C:\Users\Camila Riquelme\Desktop\pro1\app1\views.py changed, reloading.
Watching for file changes with StatReloader
Performing system checks...

Exception in thread django-main-thread:
Traceback (most recent call last):
  File "C:\Program Files\WindowsApps\PythonSoftwareFoundation.Python.3.9_3.9.496.0_x64__qbz5n2kfra8p0\lib\threading.py", line 954, in _bootstrap_inner
    self.run()
  File "C:\Program Files\WindowsApps\PythonSoftwareFoundation.Python.3.9_3.9.496.0_x64__qbz5n2kfra8p0\lib\threading.py", line 892, in run
    self._target(*self._args, **self._kwargs)
  File "C:\Users\Camila Riquelme\Documents\GitHub\pythontalentodigital2020\CODINGDOJO\django\djangoPy3Env\lib\site-packages\django\utils\autoreload.py", line 54, in wrapper
    fn(*args, **kwargs)
  File "C:\Users\Camila Riquelme\Documents\GitHub\pythontalentodigital2020\CODINGDOJO\django\djangoPy3Env\lib\site-packages\django\core\management\commands\runserver.py", line 117, in inner_run
    self.check(display_num_errors=True)
  File "C:\Users\Camila Riquelme\Documents\GitHub\pythontalentodigital2020\CODINGDOJO\django\djangoPy3Env\lib\site-packages\django\core\management\base.py", line 387, in check
    all_issues = self._run_checks(
  File "C:\Users\Camila Riquelme\Documents\GitHub\pythontalentodigital2020\CODINGDOJO\django\djangoPy3Env\lib\site-packages\django\core\management\base.py", line 377, in _run_checks
    return checks.run_checks(**kwargs)
  File "C:\Users\Camila Riquelme\Documents\GitHub\pythontalentodigital2020\CODINGDOJO\django\djangoPy3Env\lib\site-packages\django\core\checks\registry.py", line 72, in run_checks
    new_errors = check(app_configs=app_configs)
  File "C:\Users\Camila Riquelme\Documents\GitHub\pythontalentodigital2020\CODINGDOJO\django\djangoPy3Env\lib\site-packages\django\core\checks\urls.py", line 13, in check_url_config
    return check_resolver(resolver)
  File "C:\Users\Camila Riquelme\Documents\GitHub\pythontalentodigital2020\CODINGDOJO\django\djangoPy3Env\lib\site-packages\django\core\checks\urls.py", line 23, in check_resolver
    return check_method()
  File "C:\Users\Camila Riquelme\Documents\GitHub\pythontalentodigital2020\CODINGDOJO\django\djangoPy3Env\lib\site-packages\django\urls\resolvers.py", line 398, in check
    for pattern in self.url_patterns:
  File "C:\Users\Camila Riquelme\Documents\GitHub\pythontalentodigital2020\CODINGDOJO\django\djangoPy3Env\lib\site-packages\django\utils\functional.py", line 80, in __get__
    res = instance.__dict__[self.name] = self.func(instance)
  File "C:\Users\Camila Riquelme\Documents\GitHub\pythontalentodigital2020\CODINGDOJO\django\djangoPy3Env\lib\site-packages\django\urls\resolvers.py", line 579, in url_patterns
    patterns = getattr(self.urlconf_module, "urlpatterns", self.urlconf_module)
  File "C:\Users\Camila Riquelme\Documents\GitHub\pythontalentodigital2020\CODINGDOJO\django\djangoPy3Env\lib\site-packages\django\utils\functional.py", line 80, in __get__
    res = instance.__dict__[self.name] = self.func(instance)
  File "C:\Users\Camila Riquelme\Documents\GitHub\pythontalentodigital2020\CODINGDOJO\django\djangoPy3Env\lib\site-packages\django\urls\resolvers.py", line 572, in urlconf_module
    return import_module(self.urlconf_name)
  File "C:\Program Files\WindowsApps\PythonSoftwareFoundation.Python.3.9_3.9.496.0_x64__qbz5n2kfra8p0\lib\importlib\__init__.py", line 127, in import_module
    return _bootstrap._gcd_import(name[level:], package, level)
  File "<frozen importlib._bootstrap>", line 1030, in _gcd_import
  File "<frozen importlib._bootstrap>", line 1007, in _find_and_load
  File "<frozen importlib._bootstrap>", line 986, in _find_and_load_unlocked
  File "<frozen importlib._bootstrap>", line 680, in _load_unlocked
  File "<frozen importlib._bootstrap_external>", line 790, in exec_module
  File "<frozen importlib._bootstrap>", line 228, in _call_with_frames_removed
  File "C:\Users\Camila Riquelme\Desktop\pro1\pro1\urls.py", line 21, in <module>
    path('', include('app1.urls')),
  File "C:\Users\Camila Riquelme\Documents\GitHub\pythontalentodigital2020\CODINGDOJO\django\djangoPy3Env\lib\site-packages\django\urls\conf.py", line 34, 
in include
    urlconf_module = import_module(urlconf_module)
  File "C:\Program Files\WindowsApps\PythonSoftwareFoundation.Python.3.9_3.9.496.0_x64__qbz5n2kfra8p0\lib\importlib\__init__.py", line 127, in import_module
    return _bootstrap._gcd_import(name[level:], package, level)
  File "<frozen importlib._bootstrap>", line 1030, in _gcd_import
  File "<frozen importlib._bootstrap>", line 1007, in _find_and_load
  File "<frozen importlib._bootstrap>", line 986, in _find_and_load_unlocked
  File "<frozen importlib._bootstrap>", line 680, in _load_unlocked
  File "<frozen importlib._bootstrap_external>", line 790, in exec_module
  File "<frozen importlib._bootstrap>", line 228, in _call_with_frames_removed
  File "C:\Users\Camila Riquelme\Desktop\pro1\app1\urls.py", line 2, in <module>
    from . import views
  File "C:\Users\Camila Riquelme\Desktop\pro1\app1\views.py", line 13
    def awizard
               ^
SyntaxError: invalid syntax
C:\Users\Camila Riquelme\Desktop\pro1\app1\views.py changed, reloading.
Watching for file changes with StatReloader
Performing system checks...

Exception in thread django-main-thread:
Traceback (most recent call last):
  File "C:\Program Files\WindowsApps\PythonSoftwareFoundation.Python.3.9_3.9.496.0_x64__qbz5n2kfra8p0\lib\threading.py", line 954, in _bootstrap_inner     
    self.run()
  File "C:\Program Files\WindowsApps\PythonSoftwareFoundation.Python.3.9_3.9.496.0_x64__qbz5n2kfra8p0\lib\threading.py", line 892, in run
    self._target(*self._args, **self._kwargs)
  File "C:\Users\Camila Riquelme\Documents\GitHub\pythontalentodigital2020\CODINGDOJO\django\djangoPy3Env\lib\site-packages\django\utils\autoreload.py", line 54, in wrapper
    fn(*args, **kwargs)
  File "C:\Users\Camila Riquelme\Documents\GitHub\pythontalentodigital2020\CODINGDOJO\django\djangoPy3Env\lib\site-packages\django\core\management\commands\runserver.py", line 117, in inner_run
    self.check(display_num_errors=True)
  File "C:\Users\Camila Riquelme\Documents\GitHub\pythontalentodigital2020\CODINGDOJO\django\djangoPy3Env\lib\site-packages\django\core\management\base.py", line 387, in check
    all_issues = self._run_checks(
  File "C:\Users\Camila Riquelme\Documents\GitHub\pythontalentodigital2020\CODINGDOJO\django\djangoPy3Env\lib\site-packages\django\core\management\base.py", line 377, in _run_checks
    return checks.run_checks(**kwargs)
  File "C:\Users\Camila Riquelme\Documents\GitHub\pythontalentodigital2020\CODINGDOJO\django\djangoPy3Env\lib\site-packages\django\core\checks\registry.py", line 72, in run_checks
    new_errors = check(app_configs=app_configs)
  File "C:\Users\Camila Riquelme\Documents\GitHub\pythontalentodigital2020\CODINGDOJO\django\djangoPy3Env\lib\site-packages\django\core\checks\urls.py", line 13, in check_url_config
    return check_resolver(resolver)
  File "C:\Users\Camila Riquelme\Documents\GitHub\pythontalentodigital2020\CODINGDOJO\django\djangoPy3Env\lib\site-packages\django\core\checks\urls.py", line 23, in check_resolver
    return check_method()
  File "C:\Users\Camila Riquelme\Documents\GitHub\pythontalentodigital2020\CODINGDOJO\django\djangoPy3Env\lib\site-packages\django\urls\resolvers.py", line 398, in check
    for pattern in self.url_patterns:
  File "C:\Users\Camila Riquelme\Documents\GitHub\pythontalentodigital2020\CODINGDOJO\django\djangoPy3Env\lib\site-packages\django\utils\functional.py", line 80, in __get__
    res = instance.__dict__[self.name] = self.func(instance)
  File "C:\Users\Camila Riquelme\Documents\GitHub\pythontalentodigital2020\CODINGDOJO\django\djangoPy3Env\lib\site-packages\django\urls\resolvers.py", line 579, in url_patterns
    patterns = getattr(self.urlconf_module, "urlpatterns", self.urlconf_module)
  File "C:\Users\Camila Riquelme\Documents\GitHub\pythontalentodigital2020\CODINGDOJO\django\djangoPy3Env\lib\site-packages\django\utils\functional.py", line 80, in __get__
    res = instance.__dict__[self.name] = self.func(instance)
  File "C:\Users\Camila Riquelme\Documents\GitHub\pythontalentodigital2020\CODINGDOJO\django\djangoPy3Env\lib\site-packages\django\urls\resolvers.py", line 572, in urlconf_module
    return import_module(self.urlconf_name)
  File "C:\Program Files\WindowsApps\PythonSoftwareFoundation.Python.3.9_3.9.496.0_x64__qbz5n2kfra8p0\lib\importlib\__init__.py", line 127, in import_module
    return _bootstrap._gcd_import(name[level:], package, level)
  File "<frozen importlib._bootstrap>", line 1030, in _gcd_import
  File "<frozen importlib._bootstrap>", line 1007, in _find_and_load
  File "<frozen importlib._bootstrap>", line 986, in _find_and_load_unlocked
  File "<frozen importlib._bootstrap>", line 680, in _load_unlocked
  File "<frozen importlib._bootstrap_external>", line 790, in exec_module
  File "<frozen importlib._bootstrap>", line 228, in _call_with_frames_removed
  File "C:\Users\Camila Riquelme\Desktop\pro1\pro1\urls.py", line 21, in <module>
    path('', include('app1.urls')),
  File "C:\Users\Camila Riquelme\Documents\GitHub\pythontalentodigital2020\CODINGDOJO\django\djangoPy3Env\lib\site-packages\django\urls\conf.py", line 34, 
in include
    urlconf_module = import_module(urlconf_module)
  File "C:\Program Files\WindowsApps\PythonSoftwareFoundation.Python.3.9_3.9.496.0_x64__qbz5n2kfra8p0\lib\importlib\__init__.py", line 127, in import_module
    return _bootstrap._gcd_import(name[level:], package, level)
  File "<frozen importlib._bootstrap>", line 1030, in _gcd_import
  File "<frozen importlib._bootstrap>", line 1007, in _find_and_load
  File "<frozen importlib._bootstrap>", line 986, in _find_and_load_unlocked
  File "<frozen importlib._bootstrap>", line 680, in _load_unlocked
  File "<frozen importlib._bootstrap_external>", line 790, in exec_module
  File "<frozen importlib._bootstrap>", line 228, in _call_with_frames_removed
  File "C:\Users\Camila Riquelme\Desktop\pro1\app1\urls.py", line 2, in <module>
    from . import views
  File "C:\Users\Camila Riquelme\Desktop\pro1\app1\views.py", line 15

    ^
IndentationError: expected an indented block
C:\Users\Camila Riquelme\Desktop\pro1\app1\views.py changed, reloading.
Watching for file changes with StatReloader
Performing system checks...

System check identified no issues (0 silenced).
February 23, 2021 - 20:16:27
Django version 2.2.4, using settings 'pro1.settings'
Starting development server at http://127.0.0.1:8000/
Quit the server with CTRL-BREAK.
C:\Users\Camila Riquelme\Desktop\pro1\app1\views.py changed, reloading.
Watching for file changes with StatReloader
Performing system checks...

System check identified no issues (0 silenced).
February 23, 2021 - 20:16:32
Django version 2.2.4, using settings 'pro1.settings'
Starting development server at http://127.0.0.1:8000/
Quit the server with CTRL-BREAK.
C:\Users\Camila Riquelme\Desktop\pro1\app1\views.py changed, reloading.
Watching for file changes with StatReloader
Performing system checks...

System check identified no issues (0 silenced).
February 23, 2021 - 20:16:38
Django version 2.2.4, using settings 'pro1.settings'
Starting development server at http://127.0.0.1:8000/
Quit the server with CTRL-BREAK.
C:\Users\Camila Riquelme\Desktop\pro1\app1\views.py changed, reloading.
Watching for file changes with StatReloader
Performing system checks...

System check identified no issues (0 silenced).
February 23, 2021 - 20:16:44
Django version 2.2.4, using settings 'pro1.settings'
Starting development server at http://127.0.0.1:8000/
Quit the server with CTRL-BREAK.
C:\Users\Camila Riquelme\Desktop\pro1\app1\views.py changed, reloading.
Watching for file changes with StatReloader
Performing system checks...

System check identified no issues (0 silenced).
February 23, 2021 - 20:16:52
Django version 2.2.4, using settings 'pro1.settings'
Starting development server at http://127.0.0.1:8000/
Quit the server with CTRL-BREAK.
C:\Users\Camila Riquelme\Desktop\pro1\app1\views.py changed, reloading.
Watching for file changes with StatReloader
Performing system checks...

System check identified no issues (0 silenced).
February 23, 2021 - 20:16:57
Django version 2.2.4, using settings 'pro1.settings'
Starting development server at http://127.0.0.1:8000/
Quit the server with CTRL-BREAK.
C:\Users\Camila Riquelme\Desktop\pro1\app1\views.py changed, reloading.
Watching for file changes with StatReloader
Performing system checks...

System check identified no issues (0 silenced).
February 23, 2021 - 20:17:02
Django version 2.2.4, using settings 'pro1.settings'
Starting development server at http://127.0.0.1:8000/
Quit the server with CTRL-BREAK.
C:\Users\Camila Riquelme\Desktop\pro1\app1\views.py changed, reloading.
Watching for file changes with StatReloader
Performing system checks...

System check identified no issues (0 silenced).
February 23, 2021 - 20:17:06
Django version 2.2.4, using settings 'pro1.settings'
Starting development server at http://127.0.0.1:8000/
Quit the server with CTRL-BREAK.
C:\Users\Camila Riquelme\Desktop\pro1\app1\views.py changed, reloading.
Watching for file changes with StatReloader
Performing system checks...

Exception in thread django-main-thread:
Traceback (most recent call last):
  File "C:\Program Files\WindowsApps\PythonSoftwareFoundation.Python.3.9_3.9.496.0_x64__qbz5n2kfra8p0\lib\threading.py", line 954, in _bootstrap_inner     
    self.run()
  File "C:\Program Files\WindowsApps\PythonSoftwareFoundation.Python.3.9_3.9.496.0_x64__qbz5n2kfra8p0\lib\threading.py", line 892, in run
    self._target(*self._args, **self._kwargs)
  File "C:\Users\Camila Riquelme\Documents\GitHub\pythontalentodigital2020\CODINGDOJO\django\djangoPy3Env\lib\site-packages\django\utils\autoreload.py", line 54, in wrapper
    fn(*args, **kwargs)
  File "C:\Users\Camila Riquelme\Documents\GitHub\pythontalentodigital2020\CODINGDOJO\django\djangoPy3Env\lib\site-packages\django\core\management\commands\runserver.py", line 117, in inner_run
    self.check(display_num_errors=True)
  File "C:\Users\Camila Riquelme\Documents\GitHub\pythontalentodigital2020\CODINGDOJO\django\djangoPy3Env\lib\site-packages\django\core\management\base.py", line 387, in check
    all_issues = self._run_checks(
  File "C:\Users\Camila Riquelme\Documents\GitHub\pythontalentodigital2020\CODINGDOJO\django\djangoPy3Env\lib\site-packages\django\core\management\base.py", line 377, in _run_checks
    return checks.run_checks(**kwargs)
  File "C:\Users\Camila Riquelme\Documents\GitHub\pythontalentodigital2020\CODINGDOJO\django\djangoPy3Env\lib\site-packages\django\core\checks\registry.py", line 72, in run_checks
    new_errors = check(app_configs=app_configs)
  File "C:\Users\Camila Riquelme\Documents\GitHub\pythontalentodigital2020\CODINGDOJO\django\djangoPy3Env\lib\site-packages\django\core\checks\urls.py", line 13, in check_url_config
    return check_resolver(resolver)
  File "C:\Users\Camila Riquelme\Documents\GitHub\pythontalentodigital2020\CODINGDOJO\django\djangoPy3Env\lib\site-packages\django\core\checks\urls.py", line 23, in check_resolver
    return check_method()
  File "C:\Users\Camila Riquelme\Documents\GitHub\pythontalentodigital2020\CODINGDOJO\django\djangoPy3Env\lib\site-packages\django\urls\resolvers.py", line 398, in check
    for pattern in self.url_patterns:
  File "C:\Users\Camila Riquelme\Documents\GitHub\pythontalentodigital2020\CODINGDOJO\django\djangoPy3Env\lib\site-packages\django\utils\functional.py", line 80, in __get__
    res = instance.__dict__[self.name] = self.func(instance)
  File "C:\Users\Camila Riquelme\Documents\GitHub\pythontalentodigital2020\CODINGDOJO\django\djangoPy3Env\lib\site-packages\django\urls\resolvers.py", line 579, in url_patterns
    patterns = getattr(self.urlconf_module, "urlpatterns", self.urlconf_module)
  File "C:\Users\Camila Riquelme\Documents\GitHub\pythontalentodigital2020\CODINGDOJO\django\djangoPy3Env\lib\site-packages\django\utils\functional.py", line 80, in __get__
    res = instance.__dict__[self.name] = self.func(instance)
  File "C:\Users\Camila Riquelme\Documents\GitHub\pythontalentodigital2020\CODINGDOJO\django\djangoPy3Env\lib\site-packages\django\urls\resolvers.py", line 572, in urlconf_module
    return import_module(self.urlconf_name)
  File "C:\Program Files\WindowsApps\PythonSoftwareFoundation.Python.3.9_3.9.496.0_x64__qbz5n2kfra8p0\lib\importlib\__init__.py", line 127, in import_module
    return _bootstrap._gcd_import(name[level:], package, level)
  File "<frozen importlib._bootstrap>", line 1030, in _gcd_import
  File "<frozen importlib._bootstrap>", line 1007, in _find_and_load
  File "<frozen importlib._bootstrap>", line 986, in _find_and_load_unlocked
  File "<frozen importlib._bootstrap>", line 680, in _load_unlocked
  File "<frozen importlib._bootstrap_external>", line 790, in exec_module
  File "<frozen importlib._bootstrap>", line 228, in _call_with_frames_removed
  File "C:\Users\Camila Riquelme\Desktop\pro1\pro1\urls.py", line 21, in <module>
    path('', include('app1.urls')),
  File "C:\Users\Camila Riquelme\Documents\GitHub\pythontalentodigital2020\CODINGDOJO\django\djangoPy3Env\lib\site-packages\django\urls\conf.py", line 34, 
in include
    urlconf_module = import_module(urlconf_module)
  File "C:\Program Files\WindowsApps\PythonSoftwareFoundation.Python.3.9_3.9.496.0_x64__qbz5n2kfra8p0\lib\importlib\__init__.py", line 127, in import_module
    return _bootstrap._gcd_import(name[level:], package, level)
  File "<frozen importlib._bootstrap>", line 1030, in _gcd_import
  File "<frozen importlib._bootstrap>", line 1007, in _find_and_load
  File "<frozen importlib._bootstrap>", line 986, in _find_and_load_unlocked
  File "<frozen importlib._bootstrap>", line 680, in _load_unlocked
  File "<frozen importlib._bootstrap_external>", line 790, in exec_module
  File "<frozen importlib._bootstrap>", line 228, in _call_with_frames_removed
  File "C:\Users\Camila Riquelme\Desktop\pro1\app1\urls.py", line 2, in <module>
    from . import views
  File "C:\Users\Camila Riquelme\Desktop\pro1\app1\views.py", line 17
    }
    ^
SyntaxError: invalid syntax
C:\Users\Camila Riquelme\Desktop\pro1\app1\views.py changed, reloading.
Watching for file changes with StatReloader
Performing system checks...

Exception in thread django-main-thread:
Traceback (most recent call last):
  File "C:\Program Files\WindowsApps\PythonSoftwareFoundation.Python.3.9_3.9.496.0_x64__qbz5n2kfra8p0\lib\threading.py", line 954, in _bootstrap_inner     
    self.run()
  File "C:\Program Files\WindowsApps\PythonSoftwareFoundation.Python.3.9_3.9.496.0_x64__qbz5n2kfra8p0\lib\threading.py", line 892, in run
    self._target(*self._args, **self._kwargs)
  File "C:\Users\Camila Riquelme\Documents\GitHub\pythontalentodigital2020\CODINGDOJO\django\djangoPy3Env\lib\site-packages\django\utils\autoreload.py", line 54, in wrapper
    fn(*args, **kwargs)
  File "C:\Users\Camila Riquelme\Documents\GitHub\pythontalentodigital2020\CODINGDOJO\django\djangoPy3Env\lib\site-packages\django\core\management\commands\runserver.py", line 117, in inner_run
    self.check(display_num_errors=True)
  File "C:\Users\Camila Riquelme\Documents\GitHub\pythontalentodigital2020\CODINGDOJO\django\djangoPy3Env\lib\site-packages\django\core\management\base.py", line 387, in check
    all_issues = self._run_checks(
  File "C:\Users\Camila Riquelme\Documents\GitHub\pythontalentodigital2020\CODINGDOJO\django\djangoPy3Env\lib\site-packages\django\core\management\base.py", line 377, in _run_checks
    return checks.run_checks(**kwargs)
  File "C:\Users\Camila Riquelme\Documents\GitHub\pythontalentodigital2020\CODINGDOJO\django\djangoPy3Env\lib\site-packages\django\core\checks\registry.py", line 72, in run_checks
    new_errors = check(app_configs=app_configs)
  File "C:\Users\Camila Riquelme\Documents\GitHub\pythontalentodigital2020\CODINGDOJO\django\djangoPy3Env\lib\site-packages\django\core\checks\urls.py", line 13, in check_url_config
    return check_resolver(resolver)
  File "C:\Users\Camila Riquelme\Documents\GitHub\pythontalentodigital2020\CODINGDOJO\django\djangoPy3Env\lib\site-packages\django\core\checks\urls.py", line 23, in check_resolver
    return check_method()
  File "C:\Users\Camila Riquelme\Documents\GitHub\pythontalentodigital2020\CODINGDOJO\django\djangoPy3Env\lib\site-packages\django\urls\resolvers.py", line 398, in check
    for pattern in self.url_patterns:
  File "C:\Users\Camila Riquelme\Documents\GitHub\pythontalentodigital2020\CODINGDOJO\django\djangoPy3Env\lib\site-packages\django\utils\functional.py", line 80, in __get__
    res = instance.__dict__[self.name] = self.func(instance)
  File "C:\Users\Camila Riquelme\Documents\GitHub\pythontalentodigital2020\CODINGDOJO\django\djangoPy3Env\lib\site-packages\django\urls\resolvers.py", line 579, in url_patterns
    patterns = getattr(self.urlconf_module, "urlpatterns", self.urlconf_module)
  File "C:\Users\Camila Riquelme\Documents\GitHub\pythontalentodigital2020\CODINGDOJO\django\djangoPy3Env\lib\site-packages\django\utils\functional.py", line 80, in __get__
    res = instance.__dict__[self.name] = self.func(instance)
  File "C:\Users\Camila Riquelme\Documents\GitHub\pythontalentodigital2020\CODINGDOJO\django\djangoPy3Env\lib\site-packages\django\urls\resolvers.py", line 572, in urlconf_module
    return import_module(self.urlconf_name)
  File "C:\Program Files\WindowsApps\PythonSoftwareFoundation.Python.3.9_3.9.496.0_x64__qbz5n2kfra8p0\lib\importlib\__init__.py", line 127, in import_module
    return _bootstrap._gcd_import(name[level:], package, level)
  File "<frozen importlib._bootstrap>", line 1030, in _gcd_import
  File "<frozen importlib._bootstrap>", line 1007, in _find_and_load
  File "<frozen importlib._bootstrap>", line 986, in _find_and_load_unlocked
  File "<frozen importlib._bootstrap>", line 680, in _load_unlocked
  File "<frozen importlib._bootstrap_external>", line 790, in exec_module
  File "<frozen importlib._bootstrap>", line 228, in _call_with_frames_removed
  File "C:\Users\Camila Riquelme\Desktop\pro1\pro1\urls.py", line 21, in <module>
    path('', include('app1.urls')),
  File "C:\Users\Camila Riquelme\Documents\GitHub\pythontalentodigital2020\CODINGDOJO\django\djangoPy3Env\lib\site-packages\django\urls\conf.py", line 34, 
in include
    urlconf_module = import_module(urlconf_module)
  File "C:\Program Files\WindowsApps\PythonSoftwareFoundation.Python.3.9_3.9.496.0_x64__qbz5n2kfra8p0\lib\importlib\__init__.py", line 127, in import_module
    return _bootstrap._gcd_import(name[level:], package, level)
  File "<frozen importlib._bootstrap>", line 1030, in _gcd_import
  File "<frozen importlib._bootstrap>", line 1007, in _find_and_load
  File "<frozen importlib._bootstrap>", line 986, in _find_and_load_unlocked
  File "<frozen importlib._bootstrap>", line 680, in _load_unlocked
  File "<frozen importlib._bootstrap_external>", line 790, in exec_module
  File "<frozen importlib._bootstrap>", line 228, in _call_with_frames_removed
  File "C:\Users\Camila Riquelme\Desktop\pro1\app1\urls.py", line 2, in <module>
    from . import views
  File "C:\Users\Camila Riquelme\Desktop\pro1\app1\views.py", line 17
    }
    ^
SyntaxError: invalid syntax
C:\Users\Camila Riquelme\Desktop\pro1\app1\views.py changed, reloading.
Watching for file changes with StatReloader
Performing system checks...

Exception in thread django-main-thread:
Traceback (most recent call last):
  File "C:\Program Files\WindowsApps\PythonSoftwareFoundation.Python.3.9_3.9.496.0_x64__qbz5n2kfra8p0\lib\threading.py", line 954, in _bootstrap_inner     
    self.run()
  File "C:\Program Files\WindowsApps\PythonSoftwareFoundation.Python.3.9_3.9.496.0_x64__qbz5n2kfra8p0\lib\threading.py", line 892, in run
    self._target(*self._args, **self._kwargs)
  File "C:\Users\Camila Riquelme\Documents\GitHub\pythontalentodigital2020\CODINGDOJO\django\djangoPy3Env\lib\site-packages\django\utils\autoreload.py", line 54, in wrapper
    fn(*args, **kwargs)
  File "C:\Users\Camila Riquelme\Documents\GitHub\pythontalentodigital2020\CODINGDOJO\django\djangoPy3Env\lib\site-packages\django\core\management\commands\runserver.py", line 117, in inner_run
    self.check(display_num_errors=True)
  File "C:\Users\Camila Riquelme\Documents\GitHub\pythontalentodigital2020\CODINGDOJO\django\djangoPy3Env\lib\site-packages\django\core\management\base.py", line 387, in check
    all_issues = self._run_checks(
  File "C:\Users\Camila Riquelme\Documents\GitHub\pythontalentodigital2020\CODINGDOJO\django\djangoPy3Env\lib\site-packages\django\core\management\base.py", line 377, in _run_checks
    return checks.run_checks(**kwargs)
  File "C:\Users\Camila Riquelme\Documents\GitHub\pythontalentodigital2020\CODINGDOJO\django\djangoPy3Env\lib\site-packages\django\core\checks\registry.py", line 72, in run_checks
    new_errors = check(app_configs=app_configs)
  File "C:\Users\Camila Riquelme\Documents\GitHub\pythontalentodigital2020\CODINGDOJO\django\djangoPy3Env\lib\site-packages\django\core\checks\urls.py", line 13, in check_url_config
    return check_resolver(resolver)
  File "C:\Users\Camila Riquelme\Documents\GitHub\pythontalentodigital2020\CODINGDOJO\django\djangoPy3Env\lib\site-packages\django\core\checks\urls.py", line 23, in check_resolver
    return check_method()
  File "C:\Users\Camila Riquelme\Documents\GitHub\pythontalentodigital2020\CODINGDOJO\django\djangoPy3Env\lib\site-packages\django\urls\resolvers.py", line 398, in check
    for pattern in self.url_patterns:
  File "C:\Users\Camila Riquelme\Documents\GitHub\pythontalentodigital2020\CODINGDOJO\django\djangoPy3Env\lib\site-packages\django\utils\functional.py", line 80, in __get__
    res = instance.__dict__[self.name] = self.func(instance)
  File "C:\Users\Camila Riquelme\Documents\GitHub\pythontalentodigital2020\CODINGDOJO\django\djangoPy3Env\lib\site-packages\django\urls\resolvers.py", line 579, in url_patterns
    patterns = getattr(self.urlconf_module, "urlpatterns", self.urlconf_module)
  File "C:\Users\Camila Riquelme\Documents\GitHub\pythontalentodigital2020\CODINGDOJO\django\djangoPy3Env\lib\site-packages\django\utils\functional.py", line 80, in __get__
    res = instance.__dict__[self.name] = self.func(instance)
  File "C:\Users\Camila Riquelme\Documents\GitHub\pythontalentodigital2020\CODINGDOJO\django\djangoPy3Env\lib\site-packages\django\urls\resolvers.py", line 572, in urlconf_module
    return import_module(self.urlconf_name)
  File "C:\Program Files\WindowsApps\PythonSoftwareFoundation.Python.3.9_3.9.496.0_x64__qbz5n2kfra8p0\lib\importlib\__init__.py", line 127, in import_module
    return _bootstrap._gcd_import(name[level:], package, level)
  File "<frozen importlib._bootstrap>", line 1030, in _gcd_import
  File "<frozen importlib._bootstrap>", line 1007, in _find_and_load
  File "<frozen importlib._bootstrap>", line 986, in _find_and_load_unlocked
  File "<frozen importlib._bootstrap>", line 680, in _load_unlocked
  File "<frozen importlib._bootstrap_external>", line 790, in exec_module
  File "<frozen importlib._bootstrap>", line 228, in _call_with_frames_removed
  File "C:\Users\Camila Riquelme\Desktop\pro1\pro1\urls.py", line 21, in <module>
    path('', include('app1.urls')),
  File "C:\Users\Camila Riquelme\Documents\GitHub\pythontalentodigital2020\CODINGDOJO\django\djangoPy3Env\lib\site-packages\django\urls\conf.py", line 34, 
in include
    urlconf_module = import_module(urlconf_module)
  File "C:\Program Files\WindowsApps\PythonSoftwareFoundation.Python.3.9_3.9.496.0_x64__qbz5n2kfra8p0\lib\importlib\__init__.py", line 127, in import_module
    return _bootstrap._gcd_import(name[level:], package, level)
  File "<frozen importlib._bootstrap>", line 1030, in _gcd_import
  File "<frozen importlib._bootstrap>", line 1007, in _find_and_load
  File "<frozen importlib._bootstrap>", line 986, in _find_and_load_unlocked
  File "<frozen importlib._bootstrap>", line 680, in _load_unlocked
  File "<frozen importlib._bootstrap_external>", line 790, in exec_module
  File "<frozen importlib._bootstrap>", line 228, in _call_with_frames_removed
  File "C:\Users\Camila Riquelme\Desktop\pro1\app1\urls.py", line 2, in <module>
    from . import views
  File "C:\Users\Camila Riquelme\Desktop\pro1\app1\views.py", line 17
    }
    ^
SyntaxError: invalid syntax
C:\Users\Camila Riquelme\Desktop\pro1\app1\views.py changed, reloading.
Watching for file changes with StatReloader
Performing system checks...

System check identified no issues (0 silenced).
February 23, 2021 - 20:18:14
Django version 2.2.4, using settings 'pro1.settings'
Starting development server at http://127.0.0.1:8000/
Quit the server with CTRL-BREAK.
C:\Users\Camila Riquelme\Desktop\pro1\app1\views.py changed, reloading.
Watching for file changes with StatReloader
Performing system checks...

System check identified no issues (0 silenced).
February 23, 2021 - 20:18:20
Django version 2.2.4, using settings 'pro1.settings'
Starting development server at http://127.0.0.1:8000/
Quit the server with CTRL-BREAK.
C:\Users\Camila Riquelme\Desktop\pro1\app1\views.py changed, reloading.
Watching for file changes with StatReloader
Performing system checks...

System check identified no issues (0 silenced).
February 23, 2021 - 20:18:25
Django version 2.2.4, using settings 'pro1.settings'
Starting development server at http://127.0.0.1:8000/
Quit the server with CTRL-BREAK.
C:\Users\Camila Riquelme\Desktop\pro1\app1\views.py changed, reloading.
Watching for file changes with StatReloader
Performing system checks...

System check identified no issues (0 silenced).
February 23, 2021 - 20:18:30
Django version 2.2.4, using settings 'pro1.settings'
Starting development server at http://127.0.0.1:8000/
Quit the server with CTRL-BREAK.
C:\Users\Camila Riquelme\Desktop\pro1\app1\views.py changed, reloading.
Watching for file changes with StatReloader
Performing system checks...

System check identified no issues (0 silenced).
February 23, 2021 - 20:18:39
Django version 2.2.4, using settings 'pro1.settings'
Starting development server at http://127.0.0.1:8000/
Quit the server with CTRL-BREAK.
C:\Users\Camila Riquelme\Desktop\pro1\app1\urls.py changed, reloading.
Watching for file changes with StatReloader
Performing system checks...

Exception in thread django-main-thread:
Traceback (most recent call last):
  File "C:\Program Files\WindowsApps\PythonSoftwareFoundation.Python.3.9_3.9.496.0_x64__qbz5n2kfra8p0\lib\threading.py", line 954, in _bootstrap_inner     
    self.run()
  File "C:\Program Files\WindowsApps\PythonSoftwareFoundation.Python.3.9_3.9.496.0_x64__qbz5n2kfra8p0\lib\threading.py", line 892, in run
    self._target(*self._args, **self._kwargs)
  File "C:\Users\Camila Riquelme\Documents\GitHub\pythontalentodigital2020\CODINGDOJO\django\djangoPy3Env\lib\site-packages\django\utils\autoreload.py", line 54, in wrapper
    fn(*args, **kwargs)
  File "C:\Users\Camila Riquelme\Documents\GitHub\pythontalentodigital2020\CODINGDOJO\django\djangoPy3Env\lib\site-packages\django\core\management\commands\runserver.py", line 117, in inner_run
    self.check(display_num_errors=True)
  File "C:\Users\Camila Riquelme\Documents\GitHub\pythontalentodigital2020\CODINGDOJO\django\djangoPy3Env\lib\site-packages\django\core\management\base.py", line 387, in check
    all_issues = self._run_checks(
  File "C:\Users\Camila Riquelme\Documents\GitHub\pythontalentodigital2020\CODINGDOJO\django\djangoPy3Env\lib\site-packages\django\core\management\base.py", line 377, in _run_checks
    return checks.run_checks(**kwargs)
  File "C:\Users\Camila Riquelme\Documents\GitHub\pythontalentodigital2020\CODINGDOJO\django\djangoPy3Env\lib\site-packages\django\core\checks\registry.py", line 72, in run_checks
    new_errors = check(app_configs=app_configs)
  File "C:\Users\Camila Riquelme\Documents\GitHub\pythontalentodigital2020\CODINGDOJO\django\djangoPy3Env\lib\site-packages\django\core\checks\urls.py", line 13, in check_url_config
    return check_resolver(resolver)
  File "C:\Users\Camila Riquelme\Documents\GitHub\pythontalentodigital2020\CODINGDOJO\django\djangoPy3Env\lib\site-packages\django\core\checks\urls.py", line 23, in check_resolver
    return check_method()
  File "C:\Users\Camila Riquelme\Documents\GitHub\pythontalentodigital2020\CODINGDOJO\django\djangoPy3Env\lib\site-packages\django\urls\resolvers.py", line 398, in check
    for pattern in self.url_patterns:
  File "C:\Users\Camila Riquelme\Documents\GitHub\pythontalentodigital2020\CODINGDOJO\django\djangoPy3Env\lib\site-packages\django\utils\functional.py", line 80, in __get__
    res = instance.__dict__[self.name] = self.func(instance)
  File "C:\Users\Camila Riquelme\Documents\GitHub\pythontalentodigital2020\CODINGDOJO\django\djangoPy3Env\lib\site-packages\django\urls\resolvers.py", line 579, in url_patterns
    patterns = getattr(self.urlconf_module, "urlpatterns", self.urlconf_module)
  File "C:\Users\Camila Riquelme\Documents\GitHub\pythontalentodigital2020\CODINGDOJO\django\djangoPy3Env\lib\site-packages\django\utils\functional.py", line 80, in __get__
    res = instance.__dict__[self.name] = self.func(instance)
  File "C:\Users\Camila Riquelme\Documents\GitHub\pythontalentodigital2020\CODINGDOJO\django\djangoPy3Env\lib\site-packages\django\urls\resolvers.py", line 572, in urlconf_module
    return import_module(self.urlconf_name)
  File "C:\Program Files\WindowsApps\PythonSoftwareFoundation.Python.3.9_3.9.496.0_x64__qbz5n2kfra8p0\lib\importlib\__init__.py", line 127, in import_module
    return _bootstrap._gcd_import(name[level:], package, level)
  File "<frozen importlib._bootstrap>", line 1030, in _gcd_import
  File "<frozen importlib._bootstrap>", line 1007, in _find_and_load
  File "<frozen importlib._bootstrap>", line 986, in _find_and_load_unlocked
  File "<frozen importlib._bootstrap>", line 680, in _load_unlocked
  File "<frozen importlib._bootstrap_external>", line 790, in exec_module
  File "<frozen importlib._bootstrap>", line 228, in _call_with_frames_removed
  File "C:\Users\Camila Riquelme\Desktop\pro1\pro1\urls.py", line 21, in <module>
    path('', include('app1.urls')),
  File "C:\Users\Camila Riquelme\Documents\GitHub\pythontalentodigital2020\CODINGDOJO\django\djangoPy3Env\lib\site-packages\django\urls\conf.py", line 34, 
in include
    urlconf_module = import_module(urlconf_module)
  File "C:\Program Files\WindowsApps\PythonSoftwareFoundation.Python.3.9_3.9.496.0_x64__qbz5n2kfra8p0\lib\importlib\__init__.py", line 127, in import_module
    return _bootstrap._gcd_import(name[level:], package, level)
  File "<frozen importlib._bootstrap>", line 1030, in _gcd_import
  File "<frozen importlib._bootstrap>", line 1007, in _find_and_load
  File "<frozen importlib._bootstrap>", line 986, in _find_and_load_unlocked
  File "<frozen importlib._bootstrap>", line 680, in _load_unlocked
  File "<frozen importlib._bootstrap_external>", line 790, in exec_module
  File "<frozen importlib._bootstrap>", line 228, in _call_with_frames_removed
  File "C:\Users\Camila Riquelme\Desktop\pro1\app1\urls.py", line 5, in <module>
    path('')       
TypeError: _path() missing 2 required positional arguments: 'route' and 'view'
C:\Users\Camila Riquelme\Desktop\pro1\app1\urls.py changed, reloading.
Watching for file changes with StatReloader
Performing system checks...

Exception in thread django-main-thread:
Traceback (most recent call last):
  File "C:\Program Files\WindowsApps\PythonSoftwareFoundation.Python.3.9_3.9.496.0_x64__qbz5n2kfra8p0\lib\threading.py", line 954, in _bootstrap_inner     
    self.run()
  File "C:\Program Files\WindowsApps\PythonSoftwareFoundation.Python.3.9_3.9.496.0_x64__qbz5n2kfra8p0\lib\threading.py", line 892, in run
    self._target(*self._args, **self._kwargs)
  File "C:\Users\Camila Riquelme\Documents\GitHub\pythontalentodigital2020\CODINGDOJO\django\djangoPy3Env\lib\site-packages\django\utils\autoreload.py", line 54, in wrapper
    fn(*args, **kwargs)
  File "C:\Users\Camila Riquelme\Documents\GitHub\pythontalentodigital2020\CODINGDOJO\django\djangoPy3Env\lib\site-packages\django\core\management\commands\runserver.py", line 117, in inner_run
    self.check(display_num_errors=True)
  File "C:\Users\Camila Riquelme\Documents\GitHub\pythontalentodigital2020\CODINGDOJO\django\djangoPy3Env\lib\site-packages\django\core\management\base.py", line 387, in check
    all_issues = self._run_checks(
  File "C:\Users\Camila Riquelme\Documents\GitHub\pythontalentodigital2020\CODINGDOJO\django\djangoPy3Env\lib\site-packages\django\core\management\base.py", line 377, in _run_checks
    return checks.run_checks(**kwargs)
  File "C:\Users\Camila Riquelme\Documents\GitHub\pythontalentodigital2020\CODINGDOJO\django\djangoPy3Env\lib\site-packages\django\core\checks\registry.py", line 72, in run_checks
    new_errors = check(app_configs=app_configs)
  File "C:\Users\Camila Riquelme\Documents\GitHub\pythontalentodigital2020\CODINGDOJO\django\djangoPy3Env\lib\site-packages\django\core\checks\urls.py", line 13, in check_url_config
    return check_resolver(resolver)
  File "C:\Users\Camila Riquelme\Documents\GitHub\pythontalentodigital2020\CODINGDOJO\django\djangoPy3Env\lib\site-packages\django\core\checks\urls.py", line 23, in check_resolver
    return check_method()
  File "C:\Users\Camila Riquelme\Documents\GitHub\pythontalentodigital2020\CODINGDOJO\django\djangoPy3Env\lib\site-packages\django\urls\resolvers.py", line 398, in check
    for pattern in self.url_patterns:
  File "C:\Users\Camila Riquelme\Documents\GitHub\pythontalentodigital2020\CODINGDOJO\django\djangoPy3Env\lib\site-packages\django\utils\functional.py", line 80, in __get__
    res = instance.__dict__[self.name] = self.func(instance)
  File "C:\Users\Camila Riquelme\Documents\GitHub\pythontalentodigital2020\CODINGDOJO\django\djangoPy3Env\lib\site-packages\django\urls\resolvers.py", line 579, in url_patterns
    patterns = getattr(self.urlconf_module, "urlpatterns", self.urlconf_module)
  File "C:\Users\Camila Riquelme\Documents\GitHub\pythontalentodigital2020\CODINGDOJO\django\djangoPy3Env\lib\site-packages\django\utils\functional.py", line 80, in __get__
    res = instance.__dict__[self.name] = self.func(instance)
  File "C:\Users\Camila Riquelme\Documents\GitHub\pythontalentodigital2020\CODINGDOJO\django\djangoPy3Env\lib\site-packages\django\urls\resolvers.py", line 572, in urlconf_module
    return import_module(self.urlconf_name)
  File "C:\Program Files\WindowsApps\PythonSoftwareFoundation.Python.3.9_3.9.496.0_x64__qbz5n2kfra8p0\lib\importlib\__init__.py", line 127, in import_module
    return _bootstrap._gcd_import(name[level:], package, level)
  File "<frozen importlib._bootstrap>", line 1030, in _gcd_import
  File "<frozen importlib._bootstrap>", line 1007, in _find_and_load
  File "<frozen importlib._bootstrap>", line 986, in _find_and_load_unlocked
  File "<frozen importlib._bootstrap>", line 680, in _load_unlocked
  File "<frozen importlib._bootstrap_external>", line 790, in exec_module
  File "<frozen importlib._bootstrap>", line 228, in _call_with_frames_removed
  File "C:\Users\Camila Riquelme\Desktop\pro1\pro1\urls.py", line 21, in <module>
    path('', include('app1.urls')),
  File "C:\Users\Camila Riquelme\Documents\GitHub\pythontalentodigital2020\CODINGDOJO\django\djangoPy3Env\lib\site-packages\django\urls\conf.py", line 34, 
in include
    urlconf_module = import_module(urlconf_module)
  File "C:\Program Files\WindowsApps\PythonSoftwareFoundation.Python.3.9_3.9.496.0_x64__qbz5n2kfra8p0\lib\importlib\__init__.py", line 127, in import_module
    return _bootstrap._gcd_import(name[level:], package, level)
  File "<frozen importlib._bootstrap>", line 1030, in _gcd_import
  File "<frozen importlib._bootstrap>", line 1007, in _find_and_load
  File "<frozen importlib._bootstrap>", line 986, in _find_and_load_unlocked
  File "<frozen importlib._bootstrap>", line 680, in _load_unlocked
  File "<frozen importlib._bootstrap_external>", line 786, in exec_module
  File "<frozen importlib._bootstrap_external>", line 923, in get_code
  File "<frozen importlib._bootstrap_external>", line 853, in source_to_code
  File "<frozen importlib._bootstrap>", line 228, in _call_with_frames_removed
  File "C:\Users\Camila Riquelme\Desktop\pro1\app1\urls.py", line 5
    path('',views.)
                  ^
SyntaxError: invalid syntax
C:\Users\Camila Riquelme\Desktop\pro1\app1\urls.py changed, reloading.
Watching for file changes with StatReloader
Performing system checks...

System check identified no issues (0 silenced).
February 23, 2021 - 20:19:02
Django version 2.2.4, using settings 'pro1.settings'
Starting development server at http://127.0.0.1:8000/
Quit the server with CTRL-BREAK.
<QuerySet [<house: house object (1)>, <house: house object (2)>]>
[23/Feb/2021 20:27:29] "GET / HTTP/1.1" 200 830
Not Found: /process_money
[23/Feb/2021 20:27:31] "POST /process_money HTTP/1.1" 404 2271
<QuerySet [<house: house object (1)>, <house: house object (2)>]>
[23/Feb/2021 20:28:11] "GET / HTTP/1.1" 200 612
Not Found: /process_money
[23/Feb/2021 20:28:13] "POST /process_money HTTP/1.1" 404 2271
<QuerySet [<house: house object (1)>, <house: house object (2)>]>
[23/Feb/2021 20:31:28] "GET / HTTP/1.1" 200 882
Not Found: /process_money
[23/Feb/2021 20:31:38] "POST /process_money HTTP/1.1" 404 2271
Not Found: /process_money
[23/Feb/2021 20:32:52] "POST /process_money HTTP/1.1" 404 2271
Not Found: /process_money
[23/Feb/2021 20:34:20] "POST /process_money HTTP/1.1" 404 2271
<QuerySet [<house: house object (1)>, <house: house object (2)>]>
[23/Feb/2021 20:34:38] "GET / HTTP/1.1" 200 876
Not Found: /awizard
[23/Feb/2021 20:34:42] "POST /awizard HTTP/1.1" 404 2253
Not Found: /awizard
[23/Feb/2021 20:35:52] "POST /awizard HTTP/1.1" 404 2253
Not Found: /awizard
[23/Feb/2021 20:56:20] "POST /awizard HTTP/1.1" 404 2253
^C
(djangoPy3Env) C:\Users\Camila Riquelme\Desktop\pro1>

(djangoPy3Env) C:\Users\Camila Riquelme\Desktop\pro1>

(djangoPy3Env) C:\Users\Camila Riquelme\Desktop\pro1>python manage.py shell
Python 3.9.1 (tags/v3.9.1:1e5d33e, Dec  7 2020, 17:08:21) [MSC v.1927 64 bit (AMD64)] on win32
Type "help", "copyright", "credits" or "license" for more information.
(InteractiveConsole)
>>> import app1
>>> from app1.models import *  
>>> Wizard.objects.create(name="Padma Patil", house="Ravenclaw", pet="None", year="5")
Traceback (most recent call last):
  File "C:\Users\Camila Riquelme\Documents\GitHub\pythontalentodigital2020\CODINGDOJO\django\djangoPy3Env\lib\site-packages\django\db\backends\utils.py", line 84, in _execute
    return self.cursor.execute(sql, params)
  File "C:\Users\Camila Riquelme\Documents\GitHub\pythontalentodigital2020\CODINGDOJO\django\djangoPy3Env\lib\site-packages\django\db\backends\sqlite3\base.py", line 383, in execute
    return Database.Cursor.execute(self, query, params)
sqlite3.OperationalError: database is locked

The above exception was the direct cause of the following exception:

Traceback (most recent call last):
  File "<console>", line 1, in <module>
  File "C:\Users\Camila Riquelme\Documents\GitHub\pythontalentodigital2020\CODINGDOJO\django\djangoPy3Env\lib\site-packages\django\db\models\manager.py", line 82, in manager_method
    return getattr(self.get_queryset(), name)(*args, **kwargs)
  File "C:\Users\Camila Riquelme\Documents\GitHub\pythontalentodigital2020\CODINGDOJO\django\djangoPy3Env\lib\site-packages\django\db\models\query.py", line 422, in create
    obj.save(force_insert=True, using=self.db)
  File "C:\Users\Camila Riquelme\Documents\GitHub\pythontalentodigital2020\CODINGDOJO\django\djangoPy3Env\lib\site-packages\django\db\models\base.py", line 740, in save
    self.save_base(using=using, force_insert=force_insert,
  File "C:\Users\Camila Riquelme\Documents\GitHub\pythontalentodigital2020\CODINGDOJO\django\djangoPy3Env\lib\site-packages\django\db\models\base.py", line 777, in save_base
    updated = self._save_table(
  File "C:\Users\Camila Riquelme\Documents\GitHub\pythontalentodigital2020\CODINGDOJO\django\djangoPy3Env\lib\site-packages\django\db\models\base.py", line 870, in _save_table
    result = self._do_insert(cls._base_manager, using, fields, update_pk, raw)
  File "C:\Users\Camila Riquelme\Documents\GitHub\pythontalentodigital2020\CODINGDOJO\django\djangoPy3Env\lib\site-packages\django\db\models\base.py", line 907, in _do_insert
    return manager._insert([self], fields=fields, return_id=update_pk,
  File "C:\Users\Camila Riquelme\Documents\GitHub\pythontalentodigital2020\CODINGDOJO\django\djangoPy3Env\lib\site-packages\django\db\models\manager.py", line 82, in manager_method
    return getattr(self.get_queryset(), name)(*args, **kwargs)
  File "C:\Users\Camila Riquelme\Documents\GitHub\pythontalentodigital2020\CODINGDOJO\django\djangoPy3Env\lib\site-packages\django\db\models\query.py", line 1186, in _insert
    return query.get_compiler(using=using).execute_sql(return_id)
  File "C:\Users\Camila Riquelme\Documents\GitHub\pythontalentodigital2020\CODINGDOJO\django\djangoPy3Env\lib\site-packages\django\db\models\sql\compiler.py", line 1335, in execute_sql
    cursor.execute(sql, params)
  File "C:\Users\Camila Riquelme\Documents\GitHub\pythontalentodigital2020\CODINGDOJO\django\djangoPy3Env\lib\site-packages\django\db\backends\utils.py", line 99, in execute
    return super().execute(sql, params)
  File "C:\Users\Camila Riquelme\Documents\GitHub\pythontalentodigital2020\CODINGDOJO\django\djangoPy3Env\lib\site-packages\django\db\backends\utils.py", line 67, in execute
    return self._execute_with_wrappers(sql, params, many=False, executor=self._execute)
  File "C:\Users\Camila Riquelme\Documents\GitHub\pythontalentodigital2020\CODINGDOJO\django\djangoPy3Env\lib\site-packages\django\db\backends\utils.py", line 76, in _execute_with_wrappers
    return executor(sql, params, many, context)
  File "C:\Users\Camila Riquelme\Documents\GitHub\pythontalentodigital2020\CODINGDOJO\django\djangoPy3Env\lib\site-packages\django\db\backends\utils.py", line 84, in _execute
    return self.cursor.execute(sql, params)
  File "C:\Users\Camila Riquelme\Documents\GitHub\pythontalentodigital2020\CODINGDOJO\django\djangoPy3Env\lib\site-packages\django\db\utils.py", line 89, in __exit__
    raise dj_exc_value.with_traceback(traceback) from exc_value
  File "C:\Users\Camila Riquelme\Documents\GitHub\pythontalentodigital2020\CODINGDOJO\django\djangoPy3Env\lib\site-packages\django\db\backends\utils.py", line 84, in _execute
    return self.cursor.execute(sql, params)
  File "C:\Users\Camila Riquelme\Documents\GitHub\pythontalentodigital2020\CODINGDOJO\django\djangoPy3Env\lib\site-packages\django\db\backends\sqlite3\base.py", line 383, in execute
    return Database.Cursor.execute(self, query, params)
django.db.utils.OperationalError: database is locked
>>> exit(
... )

(djangoPy3Env) C:\Users\Camila Riquelme\Desktop\pro1>python manage.py makemigrations
No changes detected

(djangoPy3Env) C:\Users\Camila Riquelme\Desktop\pro1>Python manage.py migrate
Operations to perform:
  Apply all migrations: admin, app1, auth, contenttypes, sessions
Running migrations:      
  No migrations to apply.

(djangoPy3Env) C:\Users\Camila Riquelme\Desktop\pro1>Python manage.py shell          
Python 3.9.1 (tags/v3.9.1:1e5d33e, Dec  7 2020, 17:08:21) [MSC v.1927 64 bit (AMD64)] on win32
Type "help", "copyright", "credits" or "license" for more information.
(InteractiveConsole)
>>> from app1.models import *
>>> Wizard.objects.create(name="Padma Patil", house="Ravenclaw", pet="None", year=5)   
Traceback (most recent call last):
  File "C:\Users\Camila Riquelme\Documents\GitHub\pythontalentodigital2020\CODINGDOJO\django\djangoPy3Env\lib\site-packages\django\db\backends\utils.py", line 84, in _execute
    return self.cursor.execute(sql, params)
  File "C:\Users\Camila Riquelme\Documents\GitHub\pythontalentodigital2020\CODINGDOJO\django\djangoPy3Env\lib\site-packages\django\db\backends\sqlite3\base.py", line 383, in execute
    return Database.Cursor.execute(self, query, params)
sqlite3.OperationalError: database is locked

The above exception was the direct cause of the following exception:

Traceback (most recent call last):
  File "<console>", line 1, in <module>
  File "C:\Users\Camila Riquelme\Documents\GitHub\pythontalentodigital2020\CODINGDOJO\django\djangoPy3Env\lib\site-packages\django\db\models\manager.py", line 82, in manager_method
    return getattr(self.get_queryset(), name)(*args, **kwargs)
  File "C:\Users\Camila Riquelme\Documents\GitHub\pythontalentodigital2020\CODINGDOJO\django\djangoPy3Env\lib\site-packages\django\db\models\query.py", line 422, in create
    obj.save(force_insert=True, using=self.db)
  File "C:\Users\Camila Riquelme\Documents\GitHub\pythontalentodigital2020\CODINGDOJO\django\djangoPy3Env\lib\site-packages\django\db\models\base.py", line 740, in save
    self.save_base(using=using, force_insert=force_insert,
  File "C:\Users\Camila Riquelme\Documents\GitHub\pythontalentodigital2020\CODINGDOJO\django\djangoPy3Env\lib\site-packages\django\db\models\base.py", line 777, in save_base
    updated = self._save_table(
  File "C:\Users\Camila Riquelme\Documents\GitHub\pythontalentodigital2020\CODINGDOJO\django\djangoPy3Env\lib\site-packages\django\db\models\base.py", line 870, in _save_table
    result = self._do_insert(cls._base_manager, using, fields, update_pk, raw)
  File "C:\Users\Camila Riquelme\Documents\GitHub\pythontalentodigital2020\CODINGDOJO\django\djangoPy3Env\lib\site-packages\django\db\models\base.py", line 907, in _do_insert
    return manager._insert([self], fields=fields, return_id=update_pk,
  File "C:\Users\Camila Riquelme\Documents\GitHub\pythontalentodigital2020\CODINGDOJO\django\djangoPy3Env\lib\site-packages\django\db\models\manager.py", line 82, in manager_method
    return getattr(self.get_queryset(), name)(*args, **kwargs)
  File "C:\Users\Camila Riquelme\Documents\GitHub\pythontalentodigital2020\CODINGDOJO\django\djangoPy3Env\lib\site-packages\django\db\models\query.py", line 1186, in _insert
    return query.get_compiler(using=using).execute_sql(return_id)
  File "C:\Users\Camila Riquelme\Documents\GitHub\pythontalentodigital2020\CODINGDOJO\django\djangoPy3Env\lib\site-packages\django\db\models\sql\compiler.py", line 1335, in execute_sql
    cursor.execute(sql, params)
  File "C:\Users\Camila Riquelme\Documents\GitHub\pythontalentodigital2020\CODINGDOJO\django\djangoPy3Env\lib\site-packages\django\db\backends\utils.py", line 99, in execute
    return super().execute(sql, params)
  File "C:\Users\Camila Riquelme\Documents\GitHub\pythontalentodigital2020\CODINGDOJO\django\djangoPy3Env\lib\site-packages\django\db\backends\utils.py", line 67, in execute
    return self._execute_with_wrappers(sql, params, many=False, executor=self._execute)
  File "C:\Users\Camila Riquelme\Documents\GitHub\pythontalentodigital2020\CODINGDOJO\django\djangoPy3Env\lib\site-packages\django\db\backends\utils.py", line 76, in _execute_with_wrappers
    return executor(sql, params, many, context)
  File "C:\Users\Camila Riquelme\Documents\GitHub\pythontalentodigital2020\CODINGDOJO\django\djangoPy3Env\lib\site-packages\django\db\backends\utils.py", line 84, in _execute
    return self.cursor.execute(sql, params)
  File "C:\Users\Camila Riquelme\Documents\GitHub\pythontalentodigital2020\CODINGDOJO\django\djangoPy3Env\lib\site-packages\django\db\utils.py", line 89, in __exit__
    raise dj_exc_value.with_traceback(traceback) from exc_value
  File "C:\Users\Camila Riquelme\Documents\GitHub\pythontalentodigital2020\CODINGDOJO\django\djangoPy3Env\lib\site-packages\django\db\backends\utils.py", line 84, in _execute
    return self.cursor.execute(sql, params)
  File "C:\Users\Camila Riquelme\Documents\GitHub\pythontalentodigital2020\CODINGDOJO\django\djangoPy3Env\lib\site-packages\django\db\backends\sqlite3\base.py", line 383, in execute
    return Database.Cursor.execute(self, query, params)
django.db.utils.OperationalError: database is locked
>>> Wizard.objects.create(name="Padma Patil", house="Ravenclaw", pet="None", year=5)
<Wizard: Wizard object (3)>
>>> ravenclaws = Wizard.objects.filter(house="Ravenclaw")
>>> ravenclaws
<QuerySet [<Wizard: Wizard object (3)>]>
>>> ravenclaws.all()   
<QuerySet [<Wizard: Wizard object (3)>]>
>>> ravenclaws.all().values()
<QuerySet [{'id': 3, 'name': 'Padma Patil', 'house': 'Ravenclaw', 'pet': 'None', 'year': 5}]>
>>> ravenclaws.__dict__      
{'model': <class 'app1.models.Wizard'>, '_db': None, '_hints': {}, 'query': <django.db.models.sql.query.Query object at 0x0000017CDAFDCFA0>, '_result_cache': None, '_sticky_filter': False, '_for_write': False, '_prefetch_related_lookups': (), '_prefetch_done': False, '_known_related_objects': {}, '_iterable_class': <class 'django.db.models.query.ModelIterable'>, '_fields': None}
>>> ravenclaws.all().__dict__ 
{'model': <class 'app1.models.Wizard'>, '_db': None, '_hints': {}, 'query': <django.db.models.sql.query.Query object at 0x0000017CDAFDCF10>, '_result_cache': None, '_sticky_filter': False, '_for_write': False, '_prefetch_related_lookups': (), '_prefetch_done': False, '_known_related_objects': {}, '_iterable_class': <class 'django.db.models.query.ModelIterable'>, '_fields': None}
>>> ravenclaws.values()      
<QuerySet [{'id': 3, 'name': 'Padma Patil', 'house': 'Ravenclaw', 'pet': 'None', 'year': 5}]>
>>> house.values()
Traceback (most recent call last):
  File "<console>", line 1, in <module>
AttributeError: type object 'house' has no attribute 'values'
>>> house.objects.all() 
<QuerySet [<house: house object (1)>, <house: house object (2)>]>
>>> house.objects.all().values() 
<QuerySet [{'id': 1, 'name': 'slytherin', 'grade': 'one', 'created_at': None, 'updated_at': None}, {'id': 2, 'name': 'gryphindor', 'grade': 'four', 'created_at': None, 'updated_at': None}]>
>>>